<?xml version="1.0" ?>
<!-- =================================================================================== -->
<!-- |    This document was autogenerated by xacro from /home/cenk/cobot_ws/src/cobothon_ws/robot_description/urdf/orion5_main.xacro | -->
<!-- |    EDITING THIS FILE BY HAND IS NOT RECOMMENDED                                 | -->
<!-- =================================================================================== -->
<robot name="orion5">
    <material name="black">
        <color rgba="0.2 0.2 0.2 1.0" />
    </material>
    <material name="gray">
        <color rgba="0.6 0.6 0.6 1.0" />
    </material>
    <material name="blue">
        <color rgba="0.1 0.5 0.7 1.0" />
    </material>
    <link name="world" />
    <joint name="world_fixed_joint" type="fixed">
        <origin rpy="0 0 0" xyz="0.0 0.0 0.0" />
        <parent link="world" />
        <child link="base_link" />
    </joint>
    <link name="base_link">
        <inertial>
            <origin rpy="0 0 0" xyz="9.21255223397839E-07 -1.79280775157765E-06 0.024815226974079" />
            <mass value="0.769889098895433" />
            <inertia ixx="0.00118316322664961" ixy="1.14774534712335E-08" ixz="-2.43710987071992E-10" iyy="0.001183242751309" iyz="1.83744059910972E-10" izz="0.00198318001699658" />
        </inertial>
        <visual>
            <origin rpy="0 0 0" xyz="0 0 0" />
            <geometry>
                <mesh filename="package://robot_description/meshes/orion5/base_link.STL" />
            </geometry>
            <material name="blue" />
        </visual>
        <collision>
            <origin rpy="0 0 0" xyz="0 0 0" />
            <geometry>
                <mesh filename="package://robot_description/meshes/orion5/base_link.STL" />
            </geometry>
        </collision>
    </link>
    <link name="L1">
        <inertial>
            <origin rpy="0 0 0" xyz="0.0103127600446312 2.12729023838594E-06 0.0644758348429013" />
            <mass value="4.7865392773478" />
            <inertia ixx="0.0101873519511181" ixy="-4.72148313658262E-09" ixz="-0.000588650779689266" iyy="0.0114905065233776" iyz="-2.06767262963085E-08" izz="0.0108370720789659" />
        </inertial>
        <visual>
            <origin rpy="0 0 0" xyz="0 0 0" />
            <geometry>
                <mesh filename="package://robot_description/meshes/orion5/L1.STL" />
            </geometry>
            <material name="black" />
        </visual>
        <collision>
            <origin rpy="0 0 0" xyz="0 0 0" />
            <geometry>
                <mesh filename="package://robot_description/meshes/orion5/L1.STL" />
            </geometry>
        </collision>
    </link>
    <joint name="J1" type="revolute">
        <origin rpy="0 0 1.57" xyz="0 0 0.055" />
        <parent link="base_link" />
        <child link="L1" />
        <axis xyz="0 0 1" />
        <limit effort="200" lower="-3.14" upper="3.14" velocity="3.14" />
    </joint>
    <link name="L2">
        <inertial>
            <origin rpy="0 0 0" xyz="-2.59965993875612E-07 0.119821198591517 0.0651559418461157" />
            <mass value="8.30151552015886" />
            <inertia ixx="0.0328486452992198" ixy="1.03654727361315E-08" ixz="2.40742068996585E-08" iyy="0.0150283825082022" iyz="-0.000501441738539127" izz="0.032101333211442" />
        </inertial>
        <visual>
            <origin rpy="0 0 0" xyz="0 0 0" />
            <geometry>
                <mesh filename="package://robot_description/meshes/orion5/L2.STL" />
            </geometry>
            <material name="black" />
        </visual>
        <collision>
            <origin rpy="0 0 0" xyz="0 0 0" />
            <geometry>
                <mesh filename="package://robot_description/meshes/orion5/L2.STL" />
            </geometry>
        </collision>
    </link>
    <joint name="J2" type="revolute">
        <origin rpy="1.5708 0 1.5708" xyz="0.076 0 0.066" />
        <parent link="L1" />
        <child link="L2" />
        <axis xyz="0 0 1" />
        <limit effort="200" lower="-3.14" upper="3.14" velocity="3.14" />
    </joint>
    <link name="L3">
        <inertial>
            <origin rpy="0 0 0" xyz="8.0156E-08 -0.13917 0.058933" />
            <mass value="4.1211" />
            <inertia ixx="0.017469" ixy="-6.5147E-10" ixz="1.0147E-08" iyy="0.0044278" iyz="0.00075596" izz="0.01684" />
        </inertial>
        <visual>
            <origin rpy="0 0 0" xyz="0 0 0" />
            <geometry>
                <mesh filename="package://robot_description/meshes/orion5/L3.STL" />
            </geometry>
            <material name="black" />
        </visual>
        <collision>
            <origin rpy="0 0 0" xyz="0 0 0" />
            <geometry>
                <mesh filename="package://robot_description/meshes/orion5/L3.STL" />
            </geometry>
        </collision>
    </link>
    <joint name="J3" type="revolute">
        <origin rpy="3.1416 0 0" xyz="0 0.421 0.01" />
        <parent link="L2" />
        <child link="L3" />
        <axis xyz="0 0 1" />
        <limit effort="200" lower="-3.14" upper="3.14" velocity="3.14" />
    </joint>
    <link name="L4">
        <inertial>
            <origin rpy="0 0 0" xyz="-2.1724E-07 0.0023928 0.046823" />
            <mass value="0.54999" />
            <inertia ixx="0.00061299" ixy="-1.2312E-09" ixz="-4.5565E-09" iyy="0.00054583" iyz="-3.9716E-05" izz="0.00054518" />
        </inertial>
        <visual>
            <origin rpy="0 0 0" xyz="0 0 0" />
            <geometry>
                <mesh filename="package://robot_description/meshes/orion5/L4.STL" />
            </geometry>
            <material name="black" />
        </visual>
        <collision>
            <origin rpy="0 0 0" xyz="0 0 0" />
            <geometry>
                <mesh filename="package://robot_description/meshes/orion5/L4.STL" />
            </geometry>
        </collision>
    </link>
    <joint name="J4" type="revolute">
        <origin rpy="3.1416 0 0" xyz="0 -0.427 0.019" />
        <parent link="L3" />
        <child link="L4" />
        <axis xyz="0 0 1" />
        <limit effort="200" lower="-3.14" upper="3.14" velocity="3.14" />
    </joint>
    <link name="L5">
        <inertial>
            <origin rpy="0 0 0" xyz="0.0023928 -2.1726E-07 -0.046823" />
            <mass value="0.54999" />
            <inertia ixx="0.00054583" ixy="-1.2312E-09" ixz="3.9716E-05" iyy="0.00061299" iyz="4.5567E-09" izz="0.00054518" />
        </inertial>
        <visual>
            <origin rpy="0 0 0" xyz="0 0 0" />
            <geometry>
                <mesh filename="package://robot_description/meshes/orion5/L5.STL" />
            </geometry>
            <material name="black" />
        </visual>
        <collision>
            <origin rpy="0 0 0" xyz="0 0 0" />
            <geometry>
                <mesh filename="package://robot_description/meshes/orion5/L5.STL" />
            </geometry>
        </collision>
    </link>
    <joint name="J5" type="revolute">
        <origin rpy="1.5708 -1.5708 0" xyz="0 0.051 0.053" />
        <parent link="L4" />
        <child link="L5" />
        <axis xyz="0 0 1" />
        <limit effort="200" lower="-3.14" upper="3.14" velocity="3.14" />
    </joint>
    <link name="L6">
        <inertial>
            <origin rpy="0 0 0" xyz="-7.0636E-06 -0.00050194 0.018628" />
            <mass value="0.17983" />
            <inertia ixx="9.0912E-05" ixy="2.9828E-08" ixz="2.376E-08" iyy="9.1652E-05" iyz="-4.4464E-08" izz="0.00014028" />
        </inertial>
        <visual>
            <origin rpy="0 0 0" xyz="0 0 0" />
            <geometry>
                <mesh filename="package://robot_description/meshes/orion5/L6.STL" />
            </geometry>
            <material name="blue" />
        </visual>
        <collision>
            <origin rpy="0 0 0" xyz="0 0 0" />
            <geometry>
                <mesh filename="package://robot_description/meshes/orion5/L6.STL" />
            </geometry>
        </collision>
    </link>
    <joint name="J6" type="revolute">
        <origin rpy="-1.5708 0 -1.5708" xyz="0.051 0 -0.053" />
        <parent link="L5" />
        <child link="L6" />
        <axis xyz="0 0 1" />
        <limit effort="200" lower="-3.14" upper="3.14" velocity="3.14" />
    </joint>
    <joint name="gripper_joint" type="fixed">
        <parent link="L6" />
        <child link="gripper_link" />
        <origin rpy="3.14 0 3.14" xyz="0 0 0.04" />
    </joint>
    <link name="gripper_link">
        <visual>
            <origin rpy="0 0 0" xyz="-0.06 -0.06 -0.06" />
            <geometry>
                <mesh filename="package://robot_description/meshes/gripper/vacuum.STL" scale="0.001 0.001 0.001" />
            </geometry>
            <material name="black">
                <color rgba="0 0 0 1.0" />
            </material>
        </visual>
        <collision>
            <origin rpy="0 0 0" xyz="-0.06 -0.06 -0.06" />
            <geometry>
                <mesh filename="package://robot_description/meshes/gripper/vacuum.STL" scale="0.001 0.001 0.001" />
            </geometry>
        </collision>
        <inertial>
            <mass value="2.0" />
            <origin rpy="0 0 0" xyz="0 0 0" />
            <inertia ixx="0.00443333156" ixy="0.0" ixz="0.0" iyy="0.00443333156" iyz="0.0" izz="0.0072" />
        </inertial>
    </link>
    <!-- TCP link -->
    <link name="tcp_link" />
    <joint name="tcp_joint" type="fixed">
        <parent link="gripper_link" />
        <child link="tcp_link" />
        <origin rpy="-3.14 0 0" xyz="0 0 -0.06" />
    </joint>
    <transmission name="J1_tran">
        <type>transmission_interface/SimpleTransmission</type>
        <joint name="J1">
            <hardwareInterface>hardware_interface/PositionJointInterface</hardwareInterface>
        </joint>
        <actuator name="J1_actr">
            <hardwareInterface>hardware_interface/PositionJointInterface</hardwareInterface>
            <mechanicalReduction>1</mechanicalReduction>
        </actuator>
    </transmission>
    <transmission name="J2_tran">
        <type>transmission_interface/SimpleTransmission</type>
        <joint name="J2">
            <hardwareInterface>hardware_interface/PositionJointInterface</hardwareInterface>
        </joint>
        <actuator name="J2_actr">
            <hardwareInterface>hardware_interface/PositionJointInterface</hardwareInterface>
            <mechanicalReduction>1</mechanicalReduction>
        </actuator>
    </transmission>
    <transmission name="J3_tran">
        <type>transmission_interface/SimpleTransmission</type>
        <joint name="J3">
            <hardwareInterface>hardware_interface/PositionJointInterface</hardwareInterface>
        </joint>
        <actuator name="J3_actr">
            <hardwareInterface>hardware_interface/PositionJointInterface</hardwareInterface>
            <mechanicalReduction>1</mechanicalReduction>
        </actuator>
    </transmission>
    <transmission name="J4_tran">
        <type>transmission_interface/SimpleTransmission</type>
        <joint name="J4">
            <hardwareInterface>hardware_interface/PositionJointInterface</hardwareInterface>
        </joint>
        <actuator name="J4_actr">
            <hardwareInterface>hardware_interface/PositionJointInterface</hardwareInterface>
            <mechanicalReduction>1</mechanicalReduction>
        </actuator>
    </transmission>
    <transmission name="J5_tran">
        <type>transmission_interface/SimpleTransmission</type>
        <joint name="J5">
            <hardwareInterface>hardware_interface/PositionJointInterface</hardwareInterface>
        </joint>
        <actuator name="J5_actr">
            <hardwareInterface>hardware_interface/PositionJointInterface</hardwareInterface>
            <mechanicalReduction>1</mechanicalReduction>
        </actuator>
    </transmission>
    <transmission name="J6_tran">
        <type>transmission_interface/SimpleTransmission</type>
        <joint name="J6">
            <hardwareInterface>hardware_interface/PositionJointInterface</hardwareInterface>
        </joint>
        <actuator name="J6_actr">
            <hardwareInterface>hardware_interface/PositionJointInterface</hardwareInterface>
            <mechanicalReduction>1</mechanicalReduction>
        </actuator>
    </transmission>
    <!-- Gazebo Colors -->
    <gazebo reference="base_link">
        <material>Gazebo/SkyBlue</material>
        <mu1>0.2</mu1>
        <mu2>0.2</mu2>
        <selfCollide>true</selfCollide>
        <gravity>true</gravity>
    </gazebo>
    <gazebo>
        <plugin name="gazebo_ros_control" filename="libgazebo_ros_control.so"/>
    </gazebo>
    <gazebo reference="L1">
        <material>Gazebo/DarkGrey</material>
        <mu1>0.2</mu1>
        <mu2>0.2</mu2>
        <selfCollide>true</selfCollide>
    </gazebo>
    <gazebo reference="L2">
        <material>Gazebo/DarkGrey</material>
        <mu1>0.2</mu1>
        <mu2>0.2</mu2>
        <selfCollide>true</selfCollide>
    </gazebo>
    <gazebo reference="L3">
        <material>Gazebo/DarkGrey</material>
        <mu1>0.2</mu1>
        <mu2>0.2</mu2>
        <selfCollide>true</selfCollide>
    </gazebo>
    <gazebo reference="L4">
        <material>Gazebo/DarkGrey</material>
        <mu1>0.2</mu1>
        <mu2>0.2</mu2>
        <selfCollide>true</selfCollide>
    </gazebo>
    <gazebo reference="L5">
        <material>Gazebo/DarkGrey</material>
        <mu1>0.2</mu1>
        <mu2>0.2</mu2>
        <selfCollide>true</selfCollide>
    </gazebo>
    <gazebo reference="L6">
        <material>Gazebo/SkyBlue</material>
        <mu1>0.2</mu1>
        <mu2>0.2</mu2>
        <selfCollide>true</selfCollide>
    </gazebo>
    <gazebo reference="gripper_link">
        <material>Gazebo/DarkGrey</material>
        <mu1>0.2</mu1>
        <mu2>0.2</mu2>
        <selfCollide>true</selfCollide>
    </gazebo>
</robot>

